Workbook

Sheet 1-Study Identification
A1: Study Identification
A2: Study ID | B2: Title | C2: DOI | D2: Year
A3: SCOPUS-000349 | B3: Drone-Aided Detection of Weeds: Transfer Learning for Embedded Image Processing | C3: 10.1109/JSTARS.2022.3224657 | D3: 2022
A4: SCOPUS-000473 | B4: ConvNeXt based semi-supervised approach with consistency regularization for weeds classification | C4: 10.1016/j.eswa.2023.122222 | D4: 2024
A5: SCOPUS-000722 | B5: DeepVeg- Deep Learning Model for Segmentation of Weed, Canola, and Canola Flea Beetle Damage | C5: 10.1109/ACCESS.2021.3108003 | D5: 2021
A6: SCOPUS-000153 | B6: UNET-SA: A Spatial Attention Enhanced UNET for Crop–Weed Segmentation in UAV-Based Pigeon Pea Fields | C6: 10.32985/ijeces.17.4.1 | D6: 2026
A7: SCOPUS-000522 | B7: Intelligent Weed Management Based on Object Detection Neural Networks in Tomato Crops | C7: 10.3390/agronomy12122953 | D7: 2022
A8: SCOPUS-000487 | B8: Multi-Spectral Image Synthesis for Crop/Weed Segmentation in Precision Farming | C8: 10.1016/j.robot.2021.103861 | D8: 2021
A9: SCOPUS-000328 | B9: Multi-level feature re-weighted fusion for the semantic segmentation of crops and weeds | C9: 10.1016/j.jksuci.2023.03.023 | D9: 2023
A10: SCOPUS-000256 | B10: Real-Time Detection and Localization of Weeds in Dictamnus dasycarpus Fields for Laser-Based Weeding Control | C10: 10.3390/agronomy14102363 | D10: 2024
A11: SCOPUS-000234 | B11: YOLOv8 Model for Weed Detection in Wheat Fields Based on a Visual Converter and Multi-Scale Feature Fusion | C11: 10.3390/s24134379 | D11: 2024
A12: SCOPUS-000220 | B12: YOLO-SW: A Real-Time Weed Detection Model for Soybean Fields Using Swin Transformer and RT-DETR | C12: 10.3390/agronomy15071712 | D12: 2025
A13: SCOPUS-000211 | B13: HAD-YOLO: An Accurate and Effective Weed Detection Model Based on Improved YOLOV5 Network | C13: 10.3390/agronomy15010057 | D13: 2025
... A154: SCOPUS-000753 | B154: Weed detection in canola fields using maximum likelihood classification and deep convolutional neural network | C154: 10.1016/j.inpa.2019.12.002 | D154: 2020
A155: WEBSCI-000421 | B155: Benchmarking Optimizers in Transfer Learning for Automated Weed Image Recognition | D155: 2025
A156: WEBSCI-000559 | B156: Fine-grained weed recognition using Swin Transformer and two-stage transfer learning | C156: 10.3389/fpls.2023.1134932 | D156: 2023

Sheet 2-Application Context
A1: Application Context
A2: Study ID | B2: Task | C2: Crop | D2: Environment
A3: SCOPUS-000349 | B3: Segmentation | C3: None | D3: UAV aerial
A4: SCOPUS-000473 | B4: Classification | C4: Mixed | D4: Field
A5: SCOPUS-000722 | B5: Segmentation | C5: Canola | D5: Field
A6: SCOPUS-000153 | B6: Segmentation | C6: Pigeon pea | D6: Field: mobile camera (1,634 images) and UAV drone (93 images)
A7: SCOPUS-000522 | B7: Detection | C7: Tomato | D7: Field
A8: SCOPUS-000487 | B8: Segmentation | C8: Mixed | D8: Field
A9: SCOPUS-000328 | B9: Segmentation | C9: Mixed | D9: Field
A10: SCOPUS-000256 | B10: Detection | C10: Dictamnus dasycarpus | D10: Field
A11: SCOPUS-000234 | B11: Detection | C11: Wheat | D11: Field
A12: SCOPUS-000220 | B12: Detection | C12: Soybean | D12: Field
A13: SCOPUS-000211 | B13: Detection | C13: None | D13: Field
... A156: WEBSCI-000559 | B156: Classification | C156: Maize | D156: Field

Sheet 4-Dataset Characteristics
A1: Dataset Characteristics
A2: Study ID | B2: Dataset | C2: Dataset Availability | D2: Dataset Size | E2: Country
A3: SCOPUS-000349 | C3: Public | D3: >20,000 training crops; 83 evaluation crops
A4: SCOPUS-000473 | B4: DeepWeeds, 4-Weeds dataset, and CIFAR-10 | C4: Public | D4: 17509 | E4: Australia
A5: SCOPUS-000722 | B5: Canola field image dataset | C5: Private | D5: 384 | E5: Canada
A6: SCOPUS-000153 | B6: Pigeon Pea dataset | D6: 1727 | E6: India
A7: SCOPUS-000522 | C7: Private | D7: 1713 | E7: Spain
A8: SCOPUS-000487 | B8: Bonn dataset | C8: Public | D8: 2100 | E8: Germany
A9: SCOPUS-000328 | B9: BoniRob, CWFID, and Rice seedling datasets | D9: 776
A10: SCOPUS-000256 | B10: Dictamnus dasycarpus Weed Dataset | C10: On Request | D10: 3048 | E10: China
A11: SCOPUS-000234 | B11: Wheat Weed Dataset | C11: Private | D11: 4536 | E11: China
A12: SCOPUS-000220 | B12: Soybean weed dataset | C12: Public | D12: 1095 | E12: China
A13: SCOPUS-000211 | B13: National Precision Agriculture Research and Demonstration Base dataset | C13: On Request | D13: 1982 | E13: China
A14: SCOPUS-000195 | B14: Saffron weed dataset | C14: On Request | D14: 504 | E14: Iran
A15: SCOPUS-000139 | B15: Sugar beet dataset | C15: Public | D15: 2074 | E15: Germany
A16: SCOPUS-000045 | B16: Bonn sugar beet dataset | C16: Public | D16: 1600 | E16: Germany
A17: SCOPUS-000031 | B17: CropAndWeed Dataset and SB20 Dataset | C17: Public | D17: 7795 | E17: Germany
A18: SCOPUS-000014 | B18: CropAndWeed Dataset | C18: Public | D18: 7705 | E18: Austria
A19: SCOPUS-000544 | B19: Maize weed dataset | C19: Private | D19: 5856 | E19: China
A20: SCOPUS-000151 | C20: On Request | D20: 8000 | E20: China
A21: SCOPUS-000592 | C21: On Request | D21: 300 | E21: China
A22: SCOPUS-000629 | C22: On Request | D22: 884 | E22: Spain
A23: SCOPUS-000475 | B23: Sugarbeets2016 and Flourish Sapienza Datasets | C23: Public | D23: 465 | E23: Germany, Italy
A24: SCOPUS-000399 | B24: sPSD and ISAS (Institute for Sustainable Agro-ecosystem Services) dataset | C24: Public | D24: 6094 | E24: Denmark, Japan
A25: SCOPUS-000323 | B25: SorghumWeedDataset_Classification | C25: Public | D25: 4312
A26: SCOPUS-000295 | C26: Private | D26: 1500 | E26: China
A27: SCOPUS-000611 | B27: Combined dataset | C27: Public | D27: 13177 | E27: China
A28: SCOPUS-000738 | B28: Agrocam, Red Edge, and Parrot Sequoia datasets | C28: Public | D28: 679 | E28: Pakistan, Switzerland, Germany
A29: SCOPUS-000114 | B29: Custom image dataset | C29: Public | D29: 11500
A30: SCOPUS-000366 | B30: Kaggle Potato Weed Plants Classification | C30: Public | D30: 411
A31: SCOPUS-000286 | B31: Lily field image dataset | C31: On Request | D31: 1200 | E31: China
A32: SCOPUS-000283 | B32: Maize and weed dataset | C32: On Request | D32: 4465 | E32: China
A33: SCOPUS-000276 | B33: DeepWeeds | C33: Public | D33: 17509
A34: SCOPUS-000246 | B34: Custom paddy weed dataset (laboratory and field subsets) | D34: 3800 | E34: China
A35: SCOPUS-000599 | B35: Oil palm plantation weed dataset | D35: 2377 | E35: Malaysia
A36: SCOPUS-000280 | B36: Sesame dataset and Crop and Weed Detection Data with Bounding Boxes | C36: Public | D36: 4122
A37: SCOPUS-000063 | C37: On Request | D37: 7662 | E37: China
A38: SCOPUS-000017 | B38: CoFly-WeedDB and Sorghum Fields | C38: Public | D38: 7086 | E38: Greece, Germany
A39: SCOPUS-000244 | B39: DeepWeeds and CottonWeedID15 | C39: Public | D39: 22696 | E39: USA, Australia
A40: SCOPUS-000064 | C40: On Request | D40: 1308 | E40: Ethiopia
...

Sheet 5-Barrier Coding
A1: Training Data Barriers
A2: Barriers identified in each paper
A3: Study ID | B3: Study Instance ID | C3: Barrier Category | D3: Modules | E3: Barriers
A4: SCOPUS-000349 | B4: SCOPUS-000349-1 | C4: TECHNICAL | D4: Dual-camera setup | E4: Computational Resource
A5: SCOPUS-000349 | B5: SCOPUS-000349-2 | C5: IMAGING | D5: Multispectral cameras | E5: Image Alignment
A6: SCOPUS-000473 | B6: SCOPUS-000473-1 | C6: DATA | D6: Efficientnet-V2-L | E6: Data Scarcity
A7: SCOPUS-000473 | B7: SCOPUS-000473-2 | C7: ENVIRONMENTAL | D7: Efficientnet-V2-L | E7: Environmental Variation
A8: SCOPUS-000722 | B8: SCOPUS-000722-1 | C8: DATA | D8: DeepLabV3+ | E8: Class Imbalance
A9: SCOPUS-000153 | B9: SCOPUS-000153-1 | C9: DATA | D9: UNet | E9: Annotation
A10: SCOPUS-000153 | B10: SCOPUS-000153-2 | C10: IMAGING | D10: UNet | E10: Small Object Detection
A11: SCOPUS-000522 | B11: SCOPUS-000522-1 | C11: ENVIRONMENTAL | D11: YOLOv7 | E11: Background Complexity
A12: SCOPUS-000522 | B12: SCOPUS-000522-2 | C12: DATA | D12: YOLOv7 | E12: Data Scarcity
A13: SCOPUS-000487 | B13: SCOPUS-000487-1 | C13: DATA | D13: SegNet Original | E13: Data Scarcity
A14: SCOPUS-000328 | B14: SCOPUS-000328-1 | C14: ENVIRONMENTAL | E14: Background Complexity
A15: SCOPUS-000256 | B15: SCOPUS-000256-1 | C15: TECHNICAL | D15: YOLOv7-tiny | E15: Feature Representation
A16: SCOPUS-000256 | B16: SCOPUS-000256-2 | C16: IMAGING | D16: YOLOv7-tiny | E16: Image Quality
A17: SCOPUS-000234 | B17: SCOPUS-000234-1 | C17: IMAGING | D17: YOLOv3 | E17: Scale Variation
A18: SCOPUS-000220 | B18: SCOPUS-000220-1 | C18: ENVIRONMENTAL | D18: YOLOv8 | E18: Background Complexity
A19: SCOPUS-000220 | B19: SCOPUS-000220-2 | C19: IMAGING | D19: Bilinear interpolation | E19: Small Object Detection
A20: SCOPUS-000211 | B20: SCOPUS-000211-1 | C20: IMAGING | D20: YOLOV5 | E20: Small Object Detection
A21: SCOPUS-000195 | B21: SCOPUS-000195-1 | C21: IMAGING | D21: Base EfficientNetB0 | E21: Visual Similarity
A22: SCOPUS-000139 | B22: SCOPUS-000139-1 | C22: DATA | D22: YOLOv10n | E22: Data Scarcity
A23: SCOPUS-000139 | B23: SCOPUS-000139-2 | C23: ENVIRONMENTAL | D23: YOLOv10n | E23: Background Complexity
A24: SCOPUS-000045 | B24: SCOPUS-000045-1 | C24: DATA | D24: Bonnet | E24: Class Imbalance
A25: SCOPUS-000031 | B25: SCOPUS-000031-1 | C25: TECHNICAL | D25: FCN | E25: Feature Representation
A26: SCOPUS-000014 | B26: SCOPUS-000014-1 | C26: IMAGING | D26: RetinaNet | E26: Visual Similarity
... A59: SCOPUS-000064 | B59: SCOPUS-000064-2 | C59: IMAGING | D59: Fast R-CNN | E59: Image Quality
A60: SCOPUS-000320 | B60: SCOPUS-000320-1 | C60: DATA | E60: Class Imbalance
A61: SCOPUS-000086 | B61: SCOPUS-000086-1 | C61: DATA | D61: Supervised | E61: Data Scarcity
A62: SCOPUS-000652 | B62: SCOPUS-000652-1 | C62: IMAGING | D62: Vegetation Index | E62: Visual Similarity
A63: SCOPUS-000652 | B63: SCOPUS-000652-2 | C63: ENVIRONMENTAL | E63: Occlusion
A64: SCOPUS-000146 | B64: SCOPUS-000146-1 | C64: TECHNICAL | D64: VGG-16 | E64: Computational Resource
A65: SCOPUS-000146 | B65: SCOPUS-000146-2 | C65: TECHNICAL | D65: Unfolded/tabular HSI approaches | E65: Feature Representation
A66: SCOPUS-000407 | B66: SCOPUS-000407-1 | C66: ENVIRONMENTAL | D66: Yolov7 | E66: Background Complexity
A67: SCOPUS-000352 | B67: SCOPUS-000352-1 | C67: TECHNICAL | D67: UNet | E67: Computational Resource
A68: SCOPUS-000352 | B68: SCOPUS-000352-2 | C68: DATA | E68: Data Scarcity
A69: SCOPUS-000175 | B69: SCOPUS-000175-1 | C69: IMAGING | D69: YOLOv8n | E69: Visual Similarity
A70: SCOPUS-000175 | B70: SCOPUS-000175-2 | C70: ENVIRONMENTAL | E70: Occlusion
A71: SCOPUS-000574 | B71: SCOPUS-000574-1 | C71: ENVIRONMENTAL | D71: DeepLab V3+ | E71: Domain Shift
A72: SCOPUS-000358 | B72: SCOPUS-000358-1 | C72: IMAGING | D72: SegNet | E72: Visual Similarity
...

Sheet 6-Mitigation Strategy Coding
A1: Mitigation Strategies
A2: Mitigation used for each barrier
A3: Study ID | B3: Study Instance ID | C3: Mitigation Category | D3: Mitigations
A4: SCOPUS-000349 | B4: SCOPUS-000349-1 | C4: Data-Centric | D4: Transfer Learning
A5: SCOPUS-000349 | B5: SCOPUS-000349-2 | C5: Architectural | D5: Architecture Modification
A6: SCOPUS-000473 | B6: SCOPUS-000473-1 | C6: Architectural | D6: Architecture Modification
A7: SCOPUS-000473 | B7: SCOPUS-000473-2 | C7: Architectural | D7: Loss Function Modification
A8: SCOPUS-000722 | B8: SCOPUS-000722-1 | C8: Architectural | D8: Loss Function Modification
A9: SCOPUS-000153 | B9: SCOPUS-000153-1 | C9: Data-Centric | D9: Data Processing
A10: SCOPUS-000153 | B10: SCOPUS-000153-2 | C10: Architectural | D10: Attention Mechanism
A11: SCOPUS-000522 | B11: SCOPUS-000522-1 | C11: Architectural | D11: Architecture Modification
A12: SCOPUS-000522 | B12: SCOPUS-000522-2 | C12: Data-Centric | D12: Data Augmentation
A13: SCOPUS-000487 | B13: SCOPUS-000487-1 | C13: Data-Centric | D13: Synthetic Data Generation
A14: SCOPUS-000328 | B14: SCOPUS-000328-1 | C14: Architectural | D14: Attention Mechanism
... A462: WEBSCI-000559 | B462: WEBSCI-000559-4 | C462: Data-Centric | D462: Data Augmentation

Sheet 7-Baseline Performance Results
A1: Barriers-Results
A2: One primary baseline per study/task; performance gains in tab 8 are shown only for verified matched comparisons.
A3: Study ID | B3: Study Instance ID | C3: Baseline Modules | D3: Metric | E3: Metric Family | F3: Baseline (%)
A4: SCOPUS-000349 | B4: SCOPUS-000349-1 | C4: SynthNoRGN (frame-trained, test-field orthophoto) | D4: mIoU | E4: mIoU | F4: 54.5
A5: SCOPUS-000473 | B5: SCOPUS-000473-2 | C5: ConvNeXt-Base-SSL without skip connections | D5: Accuracy | E5: Accuracy | F5: 91.09
A6: SCOPUS-000722 | B6: SCOPUS-000722-1 | C6: DeepLabV3+ VGG19 | D6: mIoU | E6: mIoU | F6: 56.4739
A7: SCOPUS-000153 | B7: SCOPUS-000153-1 | C7: PAN | D7: mIoU | E7: mIoU | F7: 77.93
A8: SCOPUS-000522 | B8: SCOPUS-000522-3 | C8: RetinaNet | D8: mAP@0.5 | E8: mAP@0.5 | F8: 90.354
A9: SCOPUS-000487 | B9: SCOPUS-000487-4 | C9: Bonnet Original | D9: mIoU | E9: mIoU | F9: 70
A10: SCOPUS-000328 | B10: SCOPUS-000328-2 | C10: Baseline (paper's own base architecture, Table 4) | D10: mIoU | E10: mIoU | F10: 88.53
A11: SCOPUS-000234 | B11: SCOPUS-000234-1 | C11: YOLOv3 | D11: mAP@0.5 | E11: mAP@0.5 | F11: 73.1
A12: SCOPUS-000220 | B12: SCOPUS-000220-2 | C12: YOLOv8n | D12: mAP@0.5 | E12: mAP@0.5 | F12: 88.3
A13: SCOPUS-000211 | B13: SCOPUS-000211-2 | C13: YOLOV5 | D13: mAP (threshold unspecified) | E13: mAP (unspecified threshold) | F13: 91.6
A14: SCOPUS-000195 | B14: SCOPUS-000195-1 | C14: ResNet152 (Model 2) | D14: Accuracy | E14: Accuracy | F14: 40
A15: SCOPUS-000139 | B15: SCOPUS-000139-3 | C15: YOLOv9s (Real data only) | D15: mAP@0.5 | E15: mAP@0.5 | F15: 88.7
... A161: SCOPUS-000700 | B161: SCOPUS-000700-T1 | C161: ResNet50, standard cross-entropy, Sugar Beets weed class | D161: F1 score (weed class) | E161: F1 score | F161: 26

Sheet 8-Mitigation Performance Result
A1: Mitigation-Results
A2: Gain = each model's performance minus its study's selected baseline, in percentage points. Zero and negative differences are retained; check Audit for comparability.
A3: Study ID | B3: Study Instance ID | C3: Mitigation Modules | D3: Metric | E3: Metric Family | F3: Mitigation (%) | G3: Gain
A4: SCOPUS-000349 | B4: SCOPUS-000349-1 | C4: NoRGN (frame-trained, test-field orthophoto) | D4: mIoU | E4: mIoU | F4: 56.8 | G4: =ROUND(VALUE(F4)-'7-Baseline Performance Results'!F4,4)
A5: SCOPUS-000349 | B5: SCOPUS-000349-2 | C5: SynthFakeRGNnoTL (frame-trained, test-field orthophoto) | D5: mIoU | E5: mIoU | F5: 55.9 | G5: =ROUND(VALUE(F5)-'7-Baseline Performance Results'!F4,4)
A6: SCOPUS-000349 | B6: SCOPUS-000349-3 | C6: SynthFakeRGN+TL (frame-trained, test-field orthophoto) | D6: mIoU | E6: mIoU | F6: 60.4 | G6: =ROUND(VALUE(F6)-'7-Baseline Performance Results'!F4,4)
A7: SCOPUS-000349 | B7: SCOPUS-000349-4 | C7: TrueRGN (not tested on held-out test field) | D7: mIoU | E7: mIoU
A8: SCOPUS-000473 | B8: SCOPUS-000473-1 | C8: ViT-B-16 | D8: Accuracy | E8: Accuracy | F8: 91.1 | G8: =ROUND(VALUE(F8)-'7-Baseline Performance Results'!F5,4)
A9: SCOPUS-000473 | B9: SCOPUS-000473-2 | C9: ConvNeXt-Base-SSL with skip connections | D9: Accuracy | E9: Accuracy | F9: 92.33 | G9: =ROUND(VALUE(F9)-'7-Baseline Performance Results'!F5,4)
A10: SCOPUS-000722 | B10: SCOPUS-000722-1 | C10: Proposed | D10: mIoU | E10: mIoU | F10: 76.79226 | G10: =ROUND(VALUE(F10)-'7-Baseline Performance Results'!F6,4)
A11: SCOPUS-000153 | B11: SCOPUS-000153-1 | C11: DeepLabV3 | D11: mIoU | E11: mIoU | F11: 84.69 | G11: =ROUND(VALUE(F11)-'7-Baseline Performance Results'!F7,4)
A12: SCOPUS-000153 | B12: SCOPUS-000153-2 | C12: PSPNet | D12: mIoU | E12: mIoU | F12: 85.01 | G12: =ROUND(VALUE(F12)-'7-Baseline Performance Results'!F7,4)
A13: SCOPUS-000153 | B13: SCOPUS-000153-3 | C13: FPN | D13: mIoU | E13: mIoU | F13: 88.11 | G13: =ROUND(VALUE(F13)-'7-Baseline Performance Results'!F7,4)
A14: SCOPUS-000153 | B14: SCOPUS-000153-4 | C14: DeepLabV3+ | D14: mIoU | E14: mIoU | F14: 88.55 | G14: =ROUND(VALUE(F14)-'7-Baseline Performance Results'!F7,4)
A15: SCOPUS-000153 | B15: SCOPUS-000153-5 | C15: UPerNet | D15: mIoU | E15: mIoU | F15: 89.14 | G15: =ROUND(VALUE(F15)-'7-Baseline Performance Results'!F7,4)
A16: SCOPUS-000153 | B16: SCOPUS-000153-6 | C16: MAnet | D16: mIoU | E16: mIoU | F16: 91.95 | G16: =ROUND(VALUE(F16)-'7-Baseline Performance Results'!F7,4)
A17: SCOPUS-000153 | B17: SCOPUS-000153-7 | C17: Linknet | D17: mIoU | E17: mIoU | F17: 92.28 | G17: =ROUND(VALUE(F17)-'7-Baseline Performance Results'!F7,4)
A18: SCOPUS-000153 | B18: SCOPUS-000153-8 | C18: Unet++ | D18: mIoU | E18: mIoU | F18: 92.68 | G18: =ROUND(VALUE(F18)-'7-Baseline Performance Results'!F7,4)
A19: SCOPUS-000153 | B19: SCOPUS-000153-9 | C19: Unet | D19: mIoU | E19: mIoU | F19: 92.87 | G19: =ROUND(VALUE(F19)-'7-Baseline Performance Results'!F7,4)
A20: SCOPUS-000153 | B20: SCOPUS-000153-10 | C20: UNET-SA | D20: mIoU | E20: mIoU | F20: 94.49 | G20: =ROUND(VALUE(F20)-'7-Baseline Performance Results'!F7,4)
A21: SCOPUS-000522 | B21: SCOPUS-000522-1 | C21: YOLOv7 and Augmentation | D21: mAP@0.5 | E21: mAP@0.5 | F21: 83.085 | G21: =ROUND(VALUE(F21)-'7-Baseline Performance Results'!F8,4)
A22: SCOPUS-000522 | B22: SCOPUS-000522-2 | C22: Faster-RCNN and Augmentation | D22: mAP@0.5 | E22: mAP@0.5 | F22: 92.135 | G22: =ROUND(VALUE(F22)-'7-Baseline Performance Results'!F8,4)
A23: SCOPUS-000522 | B23: SCOPUS-000522-3 | C23: RetinaNet and Augmentation | D23: mAP@0.5 | E23: mAP@0.5 | F23: 92.755 | G23: =ROUND(VALUE(F23)-'7-Baseline Performance Results'!F8,4)
A24: SCOPUS-000487 | B24: SCOPUS-000487-1 | C24: SegNet Mixed | D24: mIoU | E24: mIoU | F24: 70 | G24: =ROUND(VALUE(F24)-'7-Baseline Performance Results'!F9,4)
A25: SCOPUS-000487 | B25: SCOPUS-000487-2 | C25: U-Net Mixed | D25: mIoU | E25: mIoU | F25: 71 | G25: =ROUND(VALUE(F25)-'7-Baseline Performance Results'!F9,4)
A26: SCOPUS-000487 | B26: SCOPUS-000487-3 | C26: UNet-ResNet Mixed | D26: mIoU | E26: mIoU | F26: 72 | G26: =ROUND(VALUE(F26)-'7-Baseline Performance Results'!F9,4)
A27: SCOPUS-000487 | B27: SCOPUS-000487-4 | C27: Bonnet Mixed | D27: mIoU | E27: mIoU | F27: 76 | G27: =ROUND(VALUE(F27)-'7-Baseline Performance Results'!F9,4)
A28: SCOPUS-000328 | B28: SCOPUS-000328-1 | C28: SEGNET | D28: mIoU | E28: mIoU | F28: 74.11 | G28: =ROUND(VALUE(F28)-'7-Baseline Performance Results'!F10,4)
A29: SCOPUS-000328 | B29: SCOPUS-000328-2 | C29: UNET | D29: mIoU | E29: mIoU | F29: 82.74 | G29: =ROUND(VALUE(F29)-'7-Baseline Performance Results'!F10,4)
A30: SCOPUS-000328 | B30: SCOPUS-000328-3 | C30: DEEPLAB3 | D30: mIoU | E30: mIoU | F30: 82.57 | G30: =ROUND(VALUE(F30)-'7-Baseline Performance Results'!F10,4)
A31: SCOPUS-000328 | B31: SCOPUS-000328-4 | C31: CED-NET | D31: mIoU | E31: mIoU | F31: 83.44 | G31: =ROUND(VALUE(F31)-'7-Baseline Performance Results'!F10,4)
A32: SCOPUS-000328 | B32: SCOPUS-000328-5 | C32: MTS-CNN | D32: mIoU | E32: mIoU | F32: 91.64 | G32: =ROUND(VALUE(F32)-'7-Baseline Performance Results'!F10,4)
A33: SCOPUS-000328 | B33: SCOPUS-000328-6 | C33: MFRWF CWF | D33: mIoU | E33: mIoU | F33: 91.64 | G33: =ROUND(VALUE(F33)-'7-Baseline Performance Results'!F10,4)
A34: SCOPUS-000234 | B34: SCOPUS-000234-1 | C34: YOLOv4-tiny | D34: mAP@0.5 | E34: mAP@0.5 | F34: 75.8 | G34: =ROUND(VALUE(F34)-'7-Baseline Performance Results'!F11,4)
A35: SCOPUS-000234 | B35: SCOPUS-000234-2 | C35: YOLOv5s | D35: mAP@0.5 | E35: mAP@0.5 | F35: 74 | G35: =ROUND(VALUE(F35)-'7-Baseline Performance Results'!F11,4)
A36: SCOPUS-000234 | B36: SCOPUS-000234-3 | C36: YOLOv7 | D36: mAP@0.5 | E36: mAP@0.5 | F36: 78.3 | G36: =ROUND(VALUE(F36)-'7-Baseline Performance Results'!F11,4)
A37: SCOPUS-000234 | B37: SCOPUS-000234-4 | C37: YOLOv9 | D37: mAP@0.5 | E37: mAP@0.5 | F37: 78.4 | G37: =ROUND(VALUE(F37)-'7-Baseline Performance Results'!F11,4)
A38: SCOPUS-000234 | B38: SCOPUS-000234-5 | C38: YOLOv8-C2f_M3-BiFPN-MPDIoU | D38: mAP@0.5 | E38: mAP@0.5 | F38: 89.7 | G38: =ROUND(VALUE(F38)-'7-Baseline Performance Results'!F11,4)
A39: SCOPUS-000220 | B39: SCOPUS-000220-2 | C39: YOLO-SW | D39: mAP@0.5 | E39: mAP@0.5 | F39: 92.3 | G39: =ROUND(VALUE(F39)-'7-Baseline Performance Results'!F12,4)
A40: SCOPUS-000211 | B40: SCOPUS-000211-1 | C40: HAD-YOLO | D40: mAP (threshold unspecified) | E40: mAP (unspecified threshold) | F40: 94.2 | G40: =ROUND(VALUE(F40)-'7-Baseline Performance Results'!F13,4)
...

Sheet 9-Quality & Risk of Bias
A1: Domain | B1: Training-Data Barriers (RQ1) | D1: Mitigation Strategy (RQ2) | F1: Performance Reporting (RQ3 & RQ4) | J1: Experimental Context (Moderators) | N1: Methodological Credibility (RQ5) | S1: Synthetic Image Methods (RQ6) | U1: Assessment Judgments
A2: Study ID | B2: Is the specific training-data barrier(s) clearly identified and described? | C2: Is the prevalence or severity of the barrier quantified or well justified? | D2: Is the mitigation strategy clearly named and described? | E2: Is the link between the barrier and the chosen strategy explicitly justified? | F2: Are absolute performance values (before and after mitigation) reported with clear metrics? | G2: Is the baseline performance (without the mitigation) clearly reported? | H2: Is the performance gain calculated and reported transparently? | I2: Are performance results supported by uncertainty/variability evidence such as repeated runs, folds, SD, CI, or multiple seeds? | J2: Is the experimental environment clearly stated (field / UAV / greenhouse / lab / controlled)? | K2: Is dataset size (number of images or instances) clearly reported? | L2: Is the computer-vision task clearly specified (Detection / Classification / Segmentation)? | M2: Is the evaluation dataset reasonably representative of the intended operating conditions? | N2: Was a proper independent test set (or external validation) used? | O2: Was data leakage prevented? | P2: Were appropriate metrics used for the task? | Q2: Are limitations of the training data and mitigation strategy discussed? | R2: Are training/validation/test samples separated sufficiently to avoid closely related images or acquisition groups appearing across splits? | S2: If synthetic images were used, is the generation method clearly described? | T2: Is a fair comparison with non-synthetic alternatives provided? | U2: Domain-level Concern | V2: Overall Risk of Bias | W2: Applicability / Generalizability Concern
A3: SCOPUS-000349 | B3: Yes | C3: Yes | D3: Yes | E3: Yes | F3: Yes | G3: Yes | H3: Yes | I3: No | J3: Yes | K3: Yes | L3: Yes | M3: Partial | N3: Yes | O3: Yes | P3: Yes | Q3: Yes | R3: Yes | S3: Yes | T3: Yes | U3: Some concerns | V3: Low | W3: Some concerns
A4: SCOPUS-000473 | B4: Yes | C4: Yes | D4: Yes | E4: Yes | F4: Yes | G4: Yes | H4: Yes | I4: Unclear | J4: Yes | K4: Yes | L4: Yes | M4: Yes | N4: Yes | O4: Partial | P4: Yes | Q4: Yes | R4: Unclear | S4: N/A | T4: N/A | U4: Some concerns | V4: Low | W4: Low
A5: SCOPUS-000722 | B5: Yes | C5: Yes | D5: Yes | E5: Yes | F5: Yes | G5: Yes | H5: Partial | I5: No | J5: Yes | K5: Yes | L5: Yes | M5: Partial | N5: Yes | O5: Unclear | P5: Yes | Q5: Yes | R5: Unclear | S5: N/A | T5: N/A | U5: Some concerns | V5: Some concerns | W5: Some concerns
A6: SCOPUS-000153 | B6: Yes | C6: Yes | D6: Yes | E6: Yes | F6: Yes | G6: Yes | H6: Yes | I6: No | J6: Yes | K6: Yes | L6: Yes | M6: Yes | N6: Yes | O6: Yes | P6: Yes | Q6: Yes | R6: Yes | S6: N/A | T6: N/A | U6: Low | V6: Low | W6: Low
A7: SCOPUS-000522 | B7: Yes | C7: Partial | D7: Yes | E7: Yes | F7: Yes | G7: Yes | H7: Partial | I7: No | J7: Yes | K7: Yes | L7: Yes | M7: Yes | N7: Yes | O7: Unclear | P7: Yes | Q7: Partial | R7: Unclear | S7: N/A | T7: N/A | U7: Some concerns | V7: Some concerns | W7: Low
A8: SCOPUS-000487 | B8: Yes | C8: Yes | D8: Yes | E8: Yes | F8: Yes | G8: Yes | H8: Yes | I8: No | J8: Yes | K8: Yes | L8: Yes | M8: Yes | N8: Yes | O8: Unclear | P8: Yes | Q8: Partial | R8: Unclear | S8: Yes | T8: Yes | U8: Some concerns | V8: Some concerns | W8: Low
A9: SCOPUS-000328 | B9: Yes | C9: Partial | D9: Yes | E9: Yes | F9: Yes | G9: Yes | H9: Partial | I9: No | J9: Yes | K9: Yes | L9: Yes | M9: Yes | N9: Yes | O9: Unclear | P9: Yes | Q9: Partial | R9: Unclear | S9: N/A | T9: N/A | U9: Some concerns | V9: Some concerns | W9: Low
A10: SCOPUS-000256 | B10: Yes | C10: Yes | D10: Yes | E10: Yes | F10: Yes | G10: Yes | H10: Yes | I10: No | J10: Yes | K10: Yes | L10: Yes | M10: Partial | N10: Yes | O10: Unclear | P10: Yes | Q10: Partial | R10: Unclear | S10: N/A | T10: N/A | U10: Some concerns | V10: Some concerns | W10: Some concerns
A11: SCOPUS-000234 | B11: Yes | C11: Yes | D11: Yes | E11: Yes | F11: Yes | G11: Yes | H11: Yes | I11: No | J11: Yes | K11: Yes | L11: Yes | M11: Partial | N11: Yes | O11: Partial | P11: Yes | Q11: Partial | R11: Unclear | S11: N/A | T11: N/A | U11: Some concerns | V11: Some concerns | W11: Some concerns
A12: SCOPUS-000220 | B12: Yes | C12: Yes | D12: Yes | E12: Yes | F12: Yes | G12: Yes | H12: Yes | I12: No | J12: Yes | K12: Yes | L12: Yes | M12: Partial | N12: Yes | O12: Unclear | P12: Yes | Q12: Partial | R12: Unclear | S12: N/A | T12: N/A | U12: Some concerns | V12: Some concerns | W12: Some concerns
A13: SCOPUS-000211 | B13: Yes | C13: Yes | D13: Yes | E13: Yes | F13: Yes | G13: Yes | H13: Yes | I13: No | J13: Yes | K13: Yes | L13: Yes | M13: Yes | N13: Yes | O13: Unclear | P13: Yes | Q13: Yes | R13: Unclear | S13: N/A | T13: N/A | U13: Some concerns | V13: Some concerns | W13: Low
... A156: WEBSCI-000559 | B156: Yes | C156: Yes | D156: Yes | E156: Yes | F156: Yes | G156: Yes | H156: Yes | I156: No | J156: Yes | K156: Yes | L156: Yes | M156: Partial | N156: Partial | O156: Unclear | P156: Yes | Q156: Yes | R156: Unclear | S156: N/A | T156: N/A | U156: Some concerns | V156: Some concerns | W156: Some concerns

Sheet 10-Source & Justification
A1: Source & Justification
A2: One row per paper -- where each performance number came from and why the mitigation was linked to it
A3: Study ID | B3: Source of Baseline | C3: Source of Best Performance | D3: Why Provided Mitigation
A4: SCOPUS-000349 | B4: Table II | C4: Table II | D4: Transfer learning is used to synthesize NIR/RGN information from RGB so the system can retain multispectral segmentation benefits while removing the extra multispectral camera, reducing hardware cost, weight, and power for practical edge deployment.
A5: SCOPUS-000473 | B5: Table 2 (without SCs, test Accuracy) | C5: Table 2 (with SCs, test Accuracy) | D5: Skip connections in the semi-supervised ConvNeXt encoder-decoder improved test accuracy under the same 20% labeled-data training conditions; this mitigation is inferred from the direct ablation.
A6: SCOPUS-000722 | B6: Table 2 | C6: Table 2 | D6: The loss and model design address extreme class imbalance and very small flea-beetle damage regions, increasing attention to poorly represented classes while preserving crop/weed segmentation boundaries.
A7: SCOPUS-000153 | B7: Table 4 | C7: Table 7 | D7: HSV mask enhancement is used to reduce annotation errors, while spatial attention is added to U-Net to focus on small or overlapping crop–weed regions and fine boundaries while suppressing irrelevant background information.
A8: SCOPUS-000522 | B8: Table 5 | C8: Table 5 | D8: RetinaNet and data augmentation are used to obtain fast one-step weed detection and classification under variable field conditions and visually similar weed species, improving robustness for real-time site-specific weed management.
A9: SCOPUS-000487 | B9: Table 3 | C9: Table 3 | D9: Synthetic multispectral crop/weed samples are generated to enlarge and diversify the small, costly pixel-wise annotated training set; mixing synthetic and real images is intended to improve segmentation generalization without equivalent manual labeling effort.
A10: SCOPUS-000328 | B10: Table 4 BoniRob own ablation: baseline mIoU 0.8853 | C10: Table 4 BoniRob own ablation: MFRWF–CWF mIoU 0.9164 | D10: The attention-based MFRWF module suppresses irrelevant background clutter and re-weights crop/weed features, while the CWF decoder preserves contextual information and limits feature distortion with low computational and memory overhead.
A11: SCOPUS-000256 | B11: Table 1 (no modules; mAP threshold unspecified) | C11: Table 1 (all modules; mAP threshold unspecified) | D11: Architecture modification in YOLO-Riny combines FasterNet, CARAFE and RepBlock for lighter, more accurate weed detection; Table 1 is the direct ablation. ByteTrack tracking outcomes are separate and not part of this mAP gain.
A12: SCOPUS-000234 | B12: Table 4 | C12: Table 4 | D12: MobileViTv3, BiFPN, and MPDIoU are introduced to handle dense, mutually occluded wheat and weeds of inconsistent sizes by combining local/global features, strengthening multi-scale fusion and small-target detection, and improving loss convergence.
A13: SCOPUS-000220 | B13: Table 2 | C13: Table 2 | D13: Swin Transformer, CARAFE, and the RT-DETR encoder are combined to improve global-context capture, preserve small-target details, reduce background and lighting interference, and maintain real-time performance for edge-deployed soybean weed detection.
A14: SCOPUS-000211 | B14: Table 2 (ablation) | C14: Table 2 (ablation) | D14: The HAD-YOLO modifications strengthen multi-scale and small-target feature extraction while making the backbone more lightweight and improving detection-head representation, addressing the difficulty of balancing weed-detection accuracy and speed.
... A157: WEBSCI-000559 | B157: Table 2 Our method Without transfer learning Accuracy = 80.00% (same MWFI testing split) | C157: Table 2 / Table 1 Our method Two-stage transfer learning Accuracy = 99.18%; ImageNet PT only = 98.57%; Table 1/3 Swin Transformer two-stage (no contrastive) = 97.96% | D157: Maize seedlings and weeds share leaf shape, MWFI has only 1632 labelled field photos, and class counts are uneven. Two-stage ImageNet→Plant Seedlings→MWFI transfer, Swin window attention, contrastive loss, and mosaic/rotation/brightness/noise augmentation are the remedies. Fair same-architecture control is Our method without TL (80.00%), not VGG-16 96.12% (weakest two-stage CNN in Table 1). Best eligible-metric model is Our method two-stage 99.18%.
